Workbook

Sheet INSTRUCTIONS
B2: INSTRUCTIONS
B3: Alliance CFO Solutions
B5: STEP 1: Export from QuickBooks Online
B6: • Go to Reports → Profit & Loss by Month
B7: • Set date range: Last 12 complete months
B8: • Export to Excel
B10: STEP 2: Paste data into DATA_INPUT tab
B11: • Column A: Account Name
B12: • Columns B through M: Monthly amounts (oldest month first)
B13: • Row 1 has headers — paste starting at Row 2
B15: STEP 3: Review the FORECAST tab
B16: • Actuals will auto-populate from DATA_INPUT
... B24: STEP 5: Review DASHBOARD for visual summary

Sheet DATA_INPUT
A1: Account Name | B1: Jan | C1: Feb | D1: Mar | E1: Apr | F1: May | G1: Jun | H1: Jul | I1: Aug | J1: Sep | K1: Oct | L1: Nov | M1: Dec
A2: Revenue - Services
A3: Revenue - Products
A4: Revenue - Other
A5: COGS - Direct Labor
A6: COGS - Materials
A7: COGS - Other
A8: Advertising
A9: Bank Charges
A10: Depreciation
A11: Insurance
A12: Office Supplies
A13: Payroll
... A20: Other Expense (non-op)

Sheet FORECAST
A1: 13-MONTH ROLLING CASH FLOW FORECAST
A2: Client: | B2: [Enter Client Name] | E2: Prepared: | F2: [Date]
A4: Category | B4: Jan | C4: Feb | D4: Mar | E4: Apr | F4: May | G4: Jun | H4: Jul | I4: Aug | J4: Sep | K4: Oct | L4: Nov | M4: Dec | N4: Month 13 Forecast
A5: REVENUE
A6: Revenue - Services
A7: Revenue - Products
A8: Revenue - Other
A9: TOTAL REVENUE | B9: =SUM(B6:B8) | C9: =SUM(C6:C8) | D9: =SUM(D6:D8) | E9: =SUM(E6:E8) | F9: =SUM(F6:F8) | G9: =SUM(G6:G8) | H9: =SUM(H6:H8) | I9: =SUM(I6:I8) | ... N9: =SUM(N6:N8)
A11: COST OF GOODS SOLD
A12: Direct Labor
A13: Materials
A14: Other COGS
A15: TOTAL COGS | B15: =SUM(B12:B14) | C15: =SUM(C12:C14) | D15: =SUM(D12:D14) | E15: =SUM(E12:E14) | F15: =SUM(F12:F14) | G15: =SUM(G12:G14) | H15: =SUM(H12:H14) | I15: =SUM(I12:I14) | ... N15: =SUM(N12:N14)
A16: GROSS PROFIT | B16: =B9-B15 | C16: =C9-C15 | D16: =D9-D15 | E16: =E9-E15 | F16: =F9-F15 | G16: =G9-G15 | H16: =H9-H15 | I16: =I9-I15 | ... N16: =N9-N15
A17: Gross Margin % | B17: =IF(B9=0,0,B16/B9) | C17: =IF(C9=0,0,C16/C9) | D17: =IF(D9=0,0,D16/D9) | E17: =IF(E9=0,0,E16/E9) | F17: =IF(F9=0,0,F16/F9) | G17: =IF(G9=0,0,G16/G9) | H17: =IF(H9=0,0,H16/H9) | I17: =IF(I9=0,0,I16/I9) | ... N17: =IF(N9=0,0,N16/N9)
A19: OPERATING EXPENSES
A20: Payroll & Benefits
A21: Rent/Lease
A22: Marketing & Advertising
A23: Insurance
A24: Office & Admin
A25: Professional Services
A26: Technology
A27: Travel
A28: Depreciation/Amortization
A29: Other Operating
A30: TOTAL OPERATING EXPENSES | B30: =SUM(B20:B29) | C30: =SUM(C20:C29) | D30: =SUM(D20:D29) | E30: =SUM(E20:E29) | F30: =SUM(F20:F29) | G30: =SUM(G20:G29) | H30: =SUM(H20:H29) | I30: =SUM(I20:I29) | ... N30: =SUM(N20:N29)
A31: OPERATING INCOME | B31: =B16-B30 | C31: =C16-C30 | D31: =D16-D30 | E31: =E16-E30 | F31: =F16-F30 | G31: =G16-G30 | H31: =H16-H30 | I31: =I16-I30 | ... N31: =N16-N30
A33: OTHER INCOME / EXPENSE
A34: Interest Income
A35: Interest Expense
A36: Other Income/Expense
A37: TOTAL OTHER | B37: =SUM(B34:B36) | C37: =SUM(C34:C36) | D37: =SUM(D34:D36) | E37: =SUM(E34:E36) | F37: =SUM(F34:F36) | G37: =SUM(G34:G36) | H37: =SUM(H34:H36) | I37: =SUM(I34:I36) | ... N37: =SUM(N34:N36)
A38: NET INCOME | B38: =B31+B37 | C38: =C31+C37 | D38: =D31+D37 | E38: =E31+E37 | F38: =F31+F37 | G38: =G31+G37 | H38: =H31+H37 | I38: =I31+I37 | ... N38: =N31+N37
A40: ADJUSTMENTS TO CASH
A41: Add: Depreciation/Amortization
A42: Changes in Accounts Receivable
A43: Changes in Accounts Payable
A44: Debt Payments
A45: Owner Distributions
...

Sheet DASHBOARD
A1: CASH FLOW DASHBOARD
A3: Month | B3: Jan | C3: Feb | D3: Mar | E3: Apr | F3: May | G3: Jun | H3: Jul | I3: Aug | J3: Sep | K3: Oct | L3: Nov | M3: Dec | N3: Forecast
A4: Ending Cash Balance | B4: =FORECAST!B51 | C4: =FORECAST!C51 | D4: =FORECAST!D51 | E4: =FORECAST!E51 | F4: =FORECAST!F51 | G4: =FORECAST!G51 | H4: =FORECAST!H51 | I4: =FORECAST!I51 | ... N4: =FORECAST!N51
A5: Net Cash Flow | B5: =FORECAST!B49 | C5: =FORECAST!C49 | D5: =FORECAST!D49 | E5: =FORECAST!E49 | F5: =FORECAST!F49 | G5: =FORECAST!G49 | H5: =FORECAST!H49 | I5: =FORECAST!I49 | ... N5: =FORECAST!N49
A8: KEY METRICS
A9: Avg Monthly Cash Flow | B9: =AVERAGE(B5:M5)
A10: Burn Rate (if negative) | B10: =IF(AVERAGE(B5:M5)<0,AVERAGE(B5:M5),0)
A11: Months of Runway | B11: =IF(B10=0,"N/A",N4/ABS(B10))
A12: Current Cash Position | B12: =N4
